<?xml version="1.0" ?>
<!-- =================================================================================== -->
<!-- |    This document was autogenerated by xacro from arm.urdf.xacro                 | -->
<!-- |    EDITING THIS FILE BY HAND IS NOT RECOMMENDED                                 | -->
<!-- =================================================================================== -->
<robot name="rc_armsim" xmlns:body="http://playerstage.sourceforge.net/gazebo/xmlschema/#body" xmlns:controller="http://playerstage.sourceforge.net/gazebo/xmlschema/#controller" xmlns:gazebo="http://playerstage.sourceforge.net/gazebo/xmlschema/#gz" xmlns:geom="http://playerstage.sourceforge.net/gazebo/xmlschema/#geom" xmlns:interface="http://playerstage.sourceforge.net/gazebo/xmlschema/#interface" xmlns:joint="http://playerstage.sourceforge.net/gazebo/xmlschema/#joint" xmlns:model="http://playerstage.sourceforge.net/gazebo/xmlschema/#model" xmlns:physics="http://playerstage.sourceforge.net/gazebo/xmlschema/#physics" xmlns:renderable="http://playerstage.sourceforge.net/gazebo/xmlschema/#renderable" xmlns:rendering="http://playerstage.sourceforge.net/gazebo/xmlschema/#rendering" xmlns:sensor="http://playerstage.sourceforge.net/gazebo/xmlschema/#sensor" xmlns:xacro="http://www.ros.org/wiki/xacro" xmlns:xi="http://www.w3.org/2001/XInclude">
  <link name="world"/>
  <joint name="fixed" type="fixed">
    <parent link="world"/>
    <child link="base_brazo_link"/>
    <origin rpy="0 0 0" xyz="0 0 0"/>
    <axis xyz="0 0 1"/>
  </joint>
  <link name="base_brazo_link">
    <visual>
      <geometry>
        <box size="0.032 0.05 0.04"/>
      </geometry>
      <origin rpy="0 0 0" xyz="0 -0.0135 0.020"/>
      <material name="black">
        <color rgba="0 0 0 1"/>
      </material>
    </visual>
    <collision>
      <origin rpy="0 0 0" xyz="0 -0.0135 0.020"/>
      <geometry>
        <box size="0.032 0.05 0.04"/>
      </geometry>
    </collision>
    <inertial>
      <origin rpy="0 0 0" xyz="0 -0.0135 0.020"/>
      <mass value="0.055"/>
      <inertia ixx="0.01" ixy="0.0" ixz="0.0" iyy="0.01" iyz="0.0" izz="0.01"/>
    </inertial>
  </link>
  <joint name="base" type="revolute">
    <parent link="base_brazo_link"/>
    <child link="hombro_link"/>
    <origin rpy="0 0 0" xyz="0 0 0.04"/>
    <axis xyz="0 0 1"/>
    <limit effort="100.0" lower="-2.62" upper="2.62" velocity="3"/>
    <dynamics damping="0" fricction="0"/>
  </joint>
  <link name="hombro_link">
    <visual>
      <geometry>
        <box size="0.04 0.032 0.05"/>
      </geometry>
      <origin rpy="0 0 0" xyz="0 0 0.025"/>
      <material name="black"/>
    </visual>
    <collision>
      <origin rpy="0 0 0" xyz="0 0 0.025"/>
      <geometry>
        <box size="0.04 0.032 0.05"/>
      </geometry>
    </collision>
    <inertial>
      <origin rpy="0 0 0" xyz="0 0 0.025"/>
      <mass value="0.055"/>
      <inertia ixx="0.01" ixy="0.0" ixz="0.0" iyy="0.01" iyz="0.0" izz="0.01"/>
    </inertial>
  </link>
  <joint name="arti1" type="revolute">
    <parent link="hombro_link"/>
    <child link="brazo_link"/>
    <origin rpy="0 0 0" xyz="0 0 0.0385"/>
    <axis xyz="1 0 0"/>
    <limit effort="100.0" lower="-2.62" upper="2.62" velocity="3"/>
    <dynamics damping="0" fricction="0"/>
  </joint>
  <!--Brazo-->
  <link name="brazo_link">
    <visual>
      <geometry>
        <box size="0.04 0.032 0.05"/>
      </geometry>
      <origin rpy="0 0 0" xyz="0 0 0.0905"/>
      <material name="black"/>
    </visual>
    <collision>
      <origin rpy="0 0 0" xyz="0 0 0.0905"/>
      <geometry>
        <box size="0.04 0.032 0.05"/>
      </geometry>
    </collision>
    <inertial>
      <origin rpy="0 0 0" xyz="0 0 0.0905"/>
      <mass value="0.055"/>
      <inertia ixx="0.01" ixy="0.0" ixz="0.0" iyy="0.01" iyz="0.0" izz="0.01"/>
    </inertial>
  </link>
  <joint name="servo_arti1_B" type="fixed">
    <parent link="brazo_link"/>
    <child link="brazo_link_B"/>
    <origin rpy="0 0 0" xyz="0 0 0"/>
    <axis xyz="1 0 0"/>
  </joint>
  <link name="brazo_link_B">
    <visual>
      <geometry>
        <box size="0.04 0.032 0.020"/>
      </geometry>
      <origin rpy="0 0 0" xyz="0 0 0.0555"/>
      <material name="white">
        <color rgba="1 1 1 1"/>
      </material>
    </visual>
    <collision>
      <origin rpy="0 0 0" xyz="0 0 0.0555"/>
      <geometry>
        <box size="0.04 0.032 0.02"/>
      </geometry>
    </collision>
    <inertial>
      <origin rpy="0 0 0" xyz="0 0 0.0555"/>
      <mass value="0.001"/>
      <inertia ixx="0.001" ixy="0.0" ixz="0.0" iyy="0.001" iyz="0.0" izz="0.001"/>
    </inertial>
  </link>
  <joint name="servo_arti1_D" type="fixed">
    <parent link="brazo_link"/>
    <child link="brazo_link_SI"/>
    <origin rpy="0 0 0" xyz="0 0 0"/>
    <axis xyz="1 0 0"/>
  </joint>
  <link name="brazo_link_SI">
    <visual>
      <geometry>
        <box size="0.002 0.032 0.067"/>
      </geometry>
      <origin rpy="0 0 0" xyz="0.021 0 0.022"/>
      <material name="white">
        <color rgba="1 1 1 1"/>
      </material>
    </visual>
    <collision>
      <origin rpy="0 0 0" xyz="0.021 0 0.022"/>
      <geometry>
        <box size="0.002 0.032 0.067"/>
      </geometry>
    </collision>
    <inertial>
      <origin rpy="0 0 0" xyz="0.021 0 0.022"/>
      <mass value="0.001"/>
      <inertia ixx="0.001" ixy="0.0" ixz="0.0" iyy="0.001" iyz="0.0" izz="0.001"/>
    </inertial>
  </link>
  <joint name="servo_arti1_I" type="fixed">
    <parent link="brazo_link"/>
    <child link="brazo_link_SD"/>
    <origin rpy="0 0 0" xyz="0 0 0"/>
    <axis xyz="1 0 0"/>
  </joint>
  <link name="brazo_link_SD">
    <visual>
      <geometry>
        <box size="0.002 0.032 0.067"/>
      </geometry>
      <origin rpy="0 0 0" xyz="-0.021 0 0.022"/>
      <material name="white">
        <color rgba="1 1 1 1"/>
      </material>
    </visual>
    <collision>
      <origin rpy="0 0 0" xyz="-0.021 0 0.022"/>
      <geometry>
        <box size="0.002 0.032 0.067"/>
      </geometry>
    </collision>
    <inertial>
      <origin rpy="0 0 0" xyz="-0.021 0 0.022"/>
      <mass value="0.001"/>
      <inertia ixx="0.001" ixy="0.0" ixz="0.0" iyy="0.001" iyz="0.0" izz="0.001"/>
    </inertial>
  </link>
  <joint name="arti2" type="revolute">
    <parent link="brazo_link"/>
    <child link="antebrazo_link"/>
    <origin rpy="0 0 0" xyz="0 0 0.104"/>
    <axis xyz="1 0 0"/>
    <limit effort="100.0" lower="-2.62" upper="2.62" velocity="3"/>
    <dynamics damping="0" fricction="0"/>
  </joint>
  <!--Antebrazo-->
  <link name="antebrazo_link">
    <visual>
      <geometry>
        <box size="0.04 0.032 0.05"/>
      </geometry>
      <origin rpy="0 0 0" xyz="0 0 0.0905"/>
      <material name="black"/>
    </visual>
    <collision>
      <origin rpy="0 0 0" xyz="0 0 0.0905"/>
      <geometry>
        <box size="0.04 0.032 0.05"/>
      </geometry>
    </collision>
    <inertial>
      <origin rpy="0 0 0" xyz="0 0 0.0905"/>
      <mass value="0.055"/>
      <inertia ixx="0.01" ixy="0.0" ixz="0.0" iyy="0.01" iyz="0.0" izz="0.01"/>
    </inertial>
  </link>
  <joint name="servo_arti2_B" type="fixed">
    <parent link="antebrazo_link"/>
    <child link="antebrazo_link_B"/>
    <origin rpy="0 0 0" xyz="0 0 0"/>
    <axis xyz="1 0 0"/>
  </joint>
  <link name="antebrazo_link_B">
    <visual>
      <geometry>
        <box size="0.04 0.032 0.020"/>
      </geometry>
      <origin rpy="0 0 0" xyz="0 0 0.0555"/>
      <material name="white">
        <color rgba="1 1 1 1"/>
      </material>
    </visual>
    <collision>
      <origin rpy="0 0 0" xyz="0 0 0.0555"/>
      <geometry>
        <box size="0.04 0.032 0.02"/>
      </geometry>
    </collision>
    <inertial>
      <origin rpy="0 0 0" xyz="0 0 0.0555"/>
      <mass value="0.001"/>
      <inertia ixx="0.001" ixy="0.0" ixz="0.0" iyy="0.001" iyz="0.0" izz="0.001"/>
    </inertial>
  </link>
  <joint name="servo_arti2_D" type="fixed">
    <parent link="antebrazo_link"/>
    <child link="antebrazo_link_SI"/>
    <origin rpy="0 0 0" xyz="0 0 0"/>
    <axis xyz="1 0 0"/>
  </joint>
  <link name="antebrazo_link_SI">
    <visual>
      <geometry>
        <box size="0.002 0.032 0.067"/>
      </geometry>
      <origin rpy="0 0 0" xyz="0.021 0 0.022"/>
      <material name="white">
        <color rgba="1 1 1 1"/>
      </material>
    </visual>
    <collision>
      <origin rpy="0 0 0" xyz="0.021 0 0.022"/>
      <geometry>
        <box size="0.002 0.032 0.067"/>
      </geometry>
    </collision>
    <inertial>
      <origin rpy="0 0 0" xyz="0.021 0 0.022"/>
      <mass value="0.001"/>
      <inertia ixx="0.001" ixy="0.0" ixz="0.0" iyy="0.001" iyz="0.0" izz="0.001"/>
    </inertial>
  </link>
  <joint name="servo_arti2_I" type="fixed">
    <parent link="antebrazo_link"/>
    <child link="antebrazo_link_SD"/>
    <origin rpy="0 0 0" xyz="0 0 0"/>
    <axis xyz="1 0 0"/>
  </joint>
  <link name="antebrazo_link_SD">
    <visual>
      <geometry>
        <box size="0.002 0.032 0.067"/>
      </geometry>
      <origin rpy="0 0 0" xyz="-0.021 0 0.022"/>
      <material name="white">
        <color rgba="1 1 1 1"/>
      </material>
    </visual>
    <collision>
      <origin rpy="0 0 0" xyz="-0.021 0 0.022"/>
      <geometry>
        <box size="0.002 0.032 0.067"/>
      </geometry>
    </collision>
    <inertial>
      <origin rpy="0 0 0" xyz="-0.021 0 0.022"/>
      <mass value="0.001"/>
      <inertia ixx="0.001" ixy="0.0" ixz="0.0" iyy="0.001" iyz="0.0" izz="0.001"/>
    </inertial>
  </link>
  <joint name="arti3" type="revolute">
    <parent link="antebrazo_link"/>
    <child link="muneca_link"/>
    <origin rpy="0 0 0" xyz="0 0 0.104"/>
    <axis xyz="1 0 0"/>
    <limit effort="100.0" lower="-2.62" upper="2.62" velocity="3"/>
    <dynamics damping="0" fricction="0"/>
  </joint>
  <!--Muneca-->
  <link name="muneca_link">
    <visual>
      <geometry>
        <box size="0.05 0.04 0.032"/>
      </geometry>
      <origin rpy="0 0 0" xyz="0.00625 0 0.06"/>
      <material name="black"/>
    </visual>
    <collision>
      <origin rpy="0 0 0" xyz="0.00625 0 0.06"/>
      <geometry>
        <box size="0.05 0.04 0.032"/>
      </geometry>
    </collision>
    <inertial>
      <origin rpy="0 0 0" xyz="0.00625 0 0.06"/>
      <mass value="0.055"/>
      <inertia ixx="0.01" ixy="0.0" ixz="0.0" iyy="0.01" iyz="0.0" izz="0.01"/>
    </inertial>
  </link>
  <joint name="servo_arti3_B" type="fixed">
    <parent link="muneca_link"/>
    <child link="muneca_link_B"/>
    <origin rpy="0 0 0" xyz="0 0 0"/>
    <axis xyz="1 0 0"/>
  </joint>
  <link name="muneca_link_B">
    <visual>
      <geometry>
        <box size="0.05325 0.04 0.005"/>
      </geometry>
      <origin rpy="0 0 0" xyz="0.004625 0 0.0415"/>
      <material name="white">
        <color rgba="1 1 1 1"/>
      </material>
    </visual>
    <collision>
      <origin rpy="0 0 0" xyz="0.004625 0 0.0415"/>
      <geometry>
        <box size="0.05325 0.04 0.005"/>
      </geometry>
    </collision>
    <inertial>
      <origin rpy="0 0 0" xyz="0.004625 0 0.0415"/>
      <mass value="0.0005"/>
      <inertia ixx="0.001" ixy="0.0" ixz="0.0" iyy="0.001" iyz="0.0" izz="0.001"/>
    </inertial>
  </link>
  <joint name="servo_arti3_D" type="fixed">
    <parent link="muneca_link"/>
    <child link="muneca_link_SI"/>
    <origin rpy="0 0 0" xyz="0 0 0"/>
    <axis xyz="1 0 0"/>
  </joint>
  <link name="muneca_link_SI">
    <visual>
      <geometry>
        <box size="0.002 0.032 0.0555"/>
      </geometry>
      <origin rpy="0 0 0" xyz="0.021 0 0.01625"/>
      <material name="white">
        <color rgba="1 1 1 1"/>
      </material>
    </visual>
    <collision>
      <origin rpy="0 0 0" xyz="0.021 0 0.01625"/>
      <geometry>
        <box size="0.002 0.032 0.0555"/>
      </geometry>
    </collision>
    <inertial>
      <origin rpy="0 0 0" xyz="0.021 0 0.01625"/>
      <mass value="0.0005"/>
      <inertia ixx="0.001" ixy="0.0" ixz="0.0" iyy="0.001" iyz="0.0" izz="0.001"/>
    </inertial>
  </link>
  <joint name="servo_arti3_I" type="fixed">
    <parent link="muneca_link"/>
    <child link="muneca_link_SD"/>
    <origin rpy="0 0 0" xyz="0 0 0"/>
    <axis xyz="1 0 0"/>
  </joint>
  <link name="muneca_link_SD">
    <visual>
      <geometry>
        <box size="0.002 0.032 0.0555"/>
      </geometry>
      <origin rpy="0 0 0" xyz="-0.021 0 0.01625"/>
      <material name="white">
        <color rgba="1 1 1 1"/>
      </material>
    </visual>
    <collision>
      <origin rpy="0 0 0" xyz="-0.021 0 0.01625"/>
      <geometry>
        <box size="0.002 0.032 0.0555"/>
      </geometry>
    </collision>
    <inertial>
      <origin rpy="0 0 0" xyz="-0.021 0 0.01625"/>
      <mass value="0.0005"/>
      <inertia ixx="0.001" ixy="0.0" ixz="0.0" iyy="0.001" iyz="0.0" izz="0.001"/>
    </inertial>
  </link>
  <joint name="servo_arti3_P" type="fixed">
    <parent link="muneca_link"/>
    <child link="muneca_link_P"/>
    <origin rpy="0 0 0" xyz="0 0 0"/>
    <axis xyz="1 0 0"/>
  </joint>
  <!--Pinza fija-->
  <link name="muneca_link_P">
    <visual>
      <geometry>
        <box size="0.002 0.04 0.092"/>
      </geometry>
      <origin rpy="0 0 0" xyz="0.03425 0 0.090"/>
      <material name="white">
        <color rgba="1 1 1 1"/>
      </material>
    </visual>
    <collision>
      <origin rpy="0 0 0" xyz="0.03425 0 0.090"/>
      <geometry>
        <box size="0.002 0.04 0.092"/>
      </geometry>
    </collision>
    <inertial>
      <origin rpy="0 0 0" xyz="0.03425 0 0.090"/>
      <mass value="0.001"/>
      <inertia ixx="0.001" ixy="0.0" ixz="0.0" iyy="0.001" iyz="0.0" izz="0.001"/>
    </inertial>
  </link>
  <joint name="servo_arti3_PS" type="fixed">
    <parent link="muneca_link"/>
    <child link="muneca_link_PS"/>
    <origin rpy="0 0 0" xyz="0 0 0"/>
    <axis xyz="1 0 0"/>
  </joint>
  <link name="muneca_link_PS">
    <visual>
      <geometry>
        <box size="0.002 0.04 0.037"/>
      </geometry>
      <origin rpy="0 0 0" xyz="0.03225 0 0.0575"/>
      <material name="white">
        <color rgba="1 1 1 1"/>
      </material>
    </visual>
    <collision>
      <origin rpy="0 0 0" xyz="0.03225 0 0.0575"/>
      <geometry>
        <box size="0.002 0.04 0.037"/>
      </geometry>
    </collision>
    <inertial>
      <origin rpy="0 0 0" xyz="0.03225 0 0.0575"/>
      <mass value="0.0005"/>
      <inertia ixx="0.001" ixy="0.0" ixz="0.0" iyy="0.001" iyz="0.0" izz="0.001"/>
    </inertial>
  </link>
  <joint name="pinza" type="revolute">
    <parent link="muneca_link"/>
    <child link="pinza_link"/>
    <origin rpy="0 0 0" xyz="-0.00725 0 0.06"/>
    <axis xyz="0 1 0"/>
    <limit effort="100.0" lower="-2.62" upper="2.62" velocity="3"/>
    <dynamics damping="0" fricction="0"/>
  </joint>
  <!--Pinza movil-->
  <link name="pinza_link">
    <visual>
      <geometry>
        <box size="0.002 0.04 0.092"/>
      </geometry>
      <origin rpy="0 0 0" xyz="-0.027 0 0.030"/>
      <material name="white">
        <color rgba="1 1 1 1"/>
      </material>
    </visual>
    <collision>
      <origin rpy="0 0 0" xyz="-0.027 0 0.030"/>
      <geometry>
        <box size="0.002 0.04 0.092"/>
      </geometry>
    </collision>
    <inertial>
      <origin rpy="0 0 0" xyz="-0.027 0 0.030"/>
      <mass value="0.001"/>
      <inertia ixx="0.001" ixy="0.0" ixz="0.0" iyy="0.001" iyz="0.0" izz="0.001"/>
    </inertial>
  </link>
  <joint name="servo_pinza_B" type="fixed">
    <parent link="pinza_link"/>
    <child link="pinza_link_B"/>
    <origin rpy="0 0 0" xyz="0 0 0"/>
    <axis xyz="1 0 0"/>
  </joint>
  <link name="pinza_link_B">
    <visual>
      <geometry>
        <box size="0.002 0.04 0.032"/>
      </geometry>
      <origin rpy="0 0 0" xyz="-0.025 0 0"/>
      <material name="white">
        <color rgba="1 1 1 1"/>
      </material>
    </visual>
    <collision>
      <origin rpy="0 0 0" xyz="-0.025 0 0"/>
      <geometry>
        <box size="0.002 0.04 0.032"/>
      </geometry>
    </collision>
    <inertial>
      <origin rpy="0 0 0" xyz="-0.025 0 0"/>
      <mass value="0.0005"/>
      <inertia ixx="0.001" ixy="0.0" ixz="0.0" iyy="0.001" iyz="0.0" izz="0.001"/>
    </inertial>
  </link>
  <joint name="servo_pinza_D" type="fixed">
    <parent link="pinza_link"/>
    <child link="pinza_link_SI"/>
    <origin rpy="0 0 0" xyz="0 0 0"/>
    <axis xyz="1 0 0"/>
  </joint>
  <link name="pinza_link_SI">
    <visual>
      <geometry>
        <box size="0.0375 0.002 0.032"/>
      </geometry>
      <origin rpy="0 0 0" xyz="-0.00725 0.021 0"/>
      <material name="white">
        <color rgba="1 1 1 1"/>
      </material>
    </visual>
    <collision>
      <origin rpy="0 0 0" xyz="-0.00725 0.021 0"/>
      <geometry>
        <box size="0.0375 0.002 0.032"/>
      </geometry>
    </collision>
    <inertial>
      <origin rpy="0 0 0" xyz="-0.00725 0.021 0"/>
      <mass value="0.0005"/>
      <inertia ixx="0.001" ixy="0.0" ixz="0.0" iyy="0.001" iyz="0.0" izz="0.001"/>
    </inertial>
  </link>
  <joint name="servo_pinza_I" type="fixed">
    <parent link="pinza_link"/>
    <child link="pinza_link_SD"/>
    <origin rpy="0 0 0" xyz="0 0 0"/>
    <axis xyz="1 0 0"/>
  </joint>
  <link name="pinza_link_SD">
    <visual>
      <geometry>
        <box size="0.0375 0.002 0.032"/>
      </geometry>
      <origin rpy="0 0 0" xyz="-0.00725 -0.021 0"/>
      <material name="white">
        <color rgba="1 1 1 1"/>
      </material>
    </visual>
    <collision>
      <origin rpy="0 0 0" xyz="-0.00725 -0.021 0"/>
      <geometry>
        <box size="0.0375 0.002 0.032"/>
      </geometry>
    </collision>
    <inertial>
      <origin rpy="0 0 0" xyz="-0.00725 -0.021 0"/>
      <mass value="0.0005"/>
      <inertia ixx="0.001" ixy="0.0" ixz="0.0" iyy="0.001" iyz="0.0" izz="0.001"/>
    </inertial>
  </link>
</robot>

