<?xml version="1.0"?>
 
<robot xmlns:xacro="http://www.ros.org/wiki/xacro">

<xacro:include filename="$(find rc_armsim)/urdf/arm_macros.xacro" />
<gazebo_propiedades_link nombre="base_brazo_link" material="Black" />
 
<gazebo_propiedades_link nombre="hombro_link" material="Black" />
 
<gazebo_propiedades_link nombre="brazo_link" material="Black" />  
 
<gazebo_propiedades_link nombre="antebrazo_link" material="Black" />
 
<gazebo_propiedades_link nombre="muneca_link" material="Black" />
 
<gazebo_propiedades_link nombre="brazo_link_B" material="White" />   
 
<gazebo_propiedades_link nombre="brazo_link_SI" material="White" /> 
 
<gazebo_propiedades_link nombre="brazo_link_SD" material="White" />     
 
 
  
<gazebo_propiedades_link nombre="muneca_link_B" material="White" />   
 
<gazebo_propiedades_link nombre="muneca_link_SI" material="White" />   
 
<gazebo_propiedades_link nombre="muneca_link_SD" material="White" />   
 
<gazebo_propiedades_link nombre="muneca_link_P" material="White" /> 
 
<gazebo_propiedades_link nombre="muneca_link_PS" material="White" />     
 
<gazebo_propiedades_link nombre="gripper_link" material="White" />   
 
<gazebo_propiedades_link nombre="gripper_link_B" material="White" />   
 
<gazebo_propiedades_link nombre="gripper_link_SI" material="White" />   
 
<gazebo_propiedades_link nombre="gripper_link_SD" material="White" /> 
 
<gazebo_propiedades_joint nombre="base" />
 
<gazebo_propiedades_joint nombre="arti1" />
 
<gazebo_propiedades_joint nombre="arti2" />
 
<gazebo_propiedades_joint nombre="arti3" />
 
<gazebo_propiedades_joint nombre="gripper" />
 
    <macro name="brazo" params="parent *origin">
 
  <joint name="fixed" type="fixed">
    <parent link="${parent}"/>
    <child link="base_brazo_link"/>
    <insert_block name="origin" />
    <axis xyz="0 0 1" />  
  </joint>
 
  <link name="base_brazo_link">
    <visual>
      <geometry>
        <cylinder length="0.04" radius="0.06"/>
      </geometry>
      <origin rpy="0 0 0" xyz="0 -0.0135 0.020"/>
      <material name="white">
        <color rgba="1 1 1 1"/>
      </material>
    </visual>
    <collision>
      <origin rpy="0 0 0" xyz="0 -0.0135 0.020"/>		
      <geometry>
        <box size="0.032 0.05 0.04"/>
      </geometry>
    </collision>
    <inertial>
      <origin rpy="0 0 0" xyz="0 -0.0135 0.020"/>			
      <mass value="0.055"/>
	  <default_inertia_servos />
    </inertial>       
  </link>
 <joint name="base" type="revolute">
    <parent link="base_brazo_link"/>
    <child link="hombro_link"/>
    <origin xyz="0 0 0.04" rpy="0 0 0" />
    <axis xyz="0 0 1" />
	<default_limit />
	<default_dynamics />          
  </joint>
 
  <link name="hombro_link">
    <visual>
      <geometry>
        <box size="0.04 0.032 0.05"/>
      </geometry>
      <origin rpy="0 0 0" xyz="0 0 0.025"/>
      <material name="black" />
    </visual>
    <collision>
      <origin rpy="0 0 0" xyz="0 0 0.025"/>		
	  <geometry>
        <box size="0.04 0.032 0.05"/>
      </geometry>       
    </collision> 
    <inertial>
      <origin rpy="0 0 0" xyz="0 0 0.025"/>			
      <mass value="0.055"/>
	  <default_inertia_servos />
    </inertial>        
  </link>  
 
  <joint name="arti1" type="revolute">
    <parent link="hombro_link"/>
    <child link="brazo_link"/>  
    <origin xyz="0 0 0.0385" rpy="0 0 0" />
	<axis xyz="1 0 0" />
	<default_limit />
	<default_dynamics />        
  </joint>
<!--Brazo-->
 
<servo nombre="brazo" />
 
  <joint name="servo_arti1_B" type="fixed">
    <parent link="brazo_link"/>
    <child link="brazo_link_B"/>  
    <origin xyz="0 0 0" rpy="0 0 0" />
	<axis xyz="1 0 0" />    
  </joint>  
 
<base nombre="brazo" /> 
 
  <joint name="servo_arti1_D" type="fixed">
    <parent link="brazo_link"/>
    <child link="brazo_link_SI"/>  
    <origin xyz="0 0 0" rpy="0 0 0" />
	<axis xyz="1 0 0" />    
  </joint>  
 
<soporte nombre="brazo" simetrico="1" lado="I" />  
 
  <joint name="servo_arti1_I" type="fixed">
    <parent link="brazo_link"/>
    <child link="brazo_link_SD"/>  
    <origin xyz="0 0 0" rpy="0 0 0" />
	<axis xyz="1 0 0" />    
  </joint>  
<soporte nombre="brazo" simetrico="-1" lado="D" />     
 
  <joint name="arti2" type="revolute">
    <parent link="brazo_link"/>
    <child link="muneca_link"/>
    <origin xyz="0 0 0.104" rpy="0 0 0" />
    <axis xyz="1 0 0" />
	<default_limit />
	<default_dynamics />            
  </joint>
 
<!--Muneca-->
 
  <link name="muneca_link">
    <visual>
      <geometry>
        <box size="0.05 0.04 0.032"/>
      </geometry>
      <origin rpy="0 0 0" xyz="0.00625 0 0.06"/>
      <material name="black" />
    </visual>
    <collision>
      <origin rpy="0 0 0" xyz="0.00625 0 0.06"/>		
	  <geometry>
        <box size="0.05 0.04 0.032"/>
      </geometry>
    </collision>
    <inertial>
      <origin rpy="0 0 0" xyz="0.00625 0 0.06"/>			
      <mass value="0.055"/>
	  <default_inertia_servos />
    </inertial>            
  </link>  
 <joint name="servo_arti3_B" type="fixed">
    <parent link="muneca_link"/>
    <child link="muneca_link_B"/>  
    <origin xyz="0 0 0" rpy="0 0 0" />
	<axis xyz="1 0 0" />    
  </joint>  
 
  <link name="muneca_link_B">    
	<visual>
      <geometry>
        <box size="0.05325 0.04 0.005"/>
      </geometry>
      <origin rpy="0 0 0" xyz="0.004625 0 0.0415"/>
      <material name="white">
		<color rgba="1 1 1 1"/>
      </material>
    </visual>
    <collision>
      <origin rpy="0 0 0" xyz="0.004625 0 0.0415"/>		
	  <geometry>
        <box size="0.05325 0.04 0.005"/>
      </geometry>
    </collision>
    <inertial>
      <origin rpy="0 0 0" xyz="0.004625 0 0.0415"/>		
      <mass value="0.0005"/>
	  <default_inertia />
    </inertial>              
  </link>
 
  <joint name="servo_arti3_D" type="fixed">
    <parent link="muneca_link"/>
    <child link="muneca_link_SI"/>  
    <origin xyz="0 0 0" rpy="0 0 0" />
	<axis xyz="1 0 0" />    
  </joint>  
 
  <link name="muneca_link_SI">    
	<visual>
      <geometry>
        <box size="0.002 0.032 0.0555"/>
      </geometry>
      <origin rpy="0 0 0" xyz="0.021 0 0.01625"/>
      <material name="white">
<color rgba="1 1 1 1"/>
      </material>
    </visual>
    <collision>
      <origin rpy="0 0 0" xyz="0.021 0 0.01625"/>		
	  <geometry>
        <box size="0.002 0.032 0.0555"/>
      </geometry>
    </collision>
    <inertial>
      <origin rpy="0 0 0" xyz="0.021 0 0.01625"/>		
      <mass value="0.0005"/>
	  <default_inertia />
    </inertial>           
  </link>
 
  <joint name="servo_arti3_I" type="fixed">
    <parent link="muneca_link"/>
    <child link="muneca_link_SD"/>  
    <origin xyz="0 0 0" rpy="0 0 0" />
	<axis xyz="1 0 0" />    
  </joint>  
 
  <link name="muneca_link_SD">    
	<visual>
      <geometry>
        <box size="0.002 0.032 0.0555"/>
      </geometry>
      <origin rpy="0 0 0" xyz="-0.021 0 0.01625"/>
      <material name="white">
		<color rgba="1 1 1 1"/>
      </material>
    </visual>
    <collision>
      <origin rpy="0 0 0" xyz="-0.021 0 0.01625"/>		
	  <geometry>
        <box size="0.002 0.032 0.0555"/>
      </geometry>
    </collision>
    <inertial>
      <origin rpy="0 0 0" xyz="-0.021 0 0.01625"/>			
      <mass value="0.0005"/>
	  <default_inertia />
    </inertial>            
  </link>
<joint name="servo_arti3_P" type="fixed">
    <parent link="muneca_link"/>
    <child link="muneca_link_P"/>  
    <origin xyz="0 0 0" rpy="0 0 0" />
	<axis xyz="1 0 0" />    
  </joint>  
 
<!--gripper fija-->
 
  <link name="muneca_link_P">    
	<visual>
      <geometry>
        <box size="0.002 0.04 0.092"/>
      </geometry>
      <origin rpy="0 0 0" xyz="0.03425 0 0.090"/>
      <material name="white">
		<color rgba="1 1 1 1"/>
      </material>
    </visual>
    <collision>
      <origin rpy="0 0 0" xyz="0.03425 0 0.090"/>		
	  <geometry>
        <box size="0.002 0.04 0.092"/>
      </geometry>
    </collision>
    <inertial>
      <origin rpy="0 0 0" xyz="0.03425 0 0.090"/>			
      <mass value="0.001"/>
	  <default_inertia />
    </inertial>           
  </link>
 
  <joint name="servo_arti3_PS" type="fixed">
    <parent link="muneca_link"/>
    <child link="muneca_link_PS"/>  
    <origin xyz="0 0 0" rpy="0 0 0" />
	<axis xyz="1 0 0" />    
  </joint>
 
  <link name="muneca_link_PS">    
	<visual>
      <geometry>
        <box size="0.002 0.04 0.037"/>
      </geometry>
      <origin rpy="0 0 0" xyz="0.03225 0 0.0575"/>
      <material name="white">
		<color rgba="1 1 1 1"/>
      </material>
    </visual>
    <collision>
      <origin rpy="0 0 0" xyz="0.03225 0 0.0575"/>	
	  <geometry>
        <box size="0.002 0.04 0.037"/>
      </geometry>
    </collision>
    <inertial>
      <origin rpy="0 0 0" xyz="0.03225 0 0.0575"/>			
      <mass value="0.0005"/>
	  <default_inertia />
    </inertial>            
  </link>             
 
  <joint name="gripper" type="revolute">
    <parent link="muneca_link"/>
    <child link="gripper_link"/>
    <origin xyz="-0.00725 0 0.06" rpy="0 0 0" />
    <axis xyz="0 1 0" />
	<default_limit />
	<default_dynamics />     
  </joint>
 
<!--gripper movil-->
 
  <link name="gripper_link">    
	<visual>
      <geometry>
        <box size="0.002 0.04 0.092"/>
      </geometry>
      <origin rpy="0 0 0" xyz="-0.027 0 0.030"/>
      <material name="white">
		<color rgba="1 1 1 1"/>
      </material>
    </visual>
    <collision>
      <origin rpy="0 0 0" xyz="-0.027 0 0.030"/>		
	  <geometry>
        <box size="0.002 0.04 0.092"/>
      </geometry>
    </collision>
    <inertial>
      <origin rpy="0 0 0" xyz="-0.027 0 0.030"/>		
      <mass value="0.001"/>
 	  <default_inertia />
    </inertial>           
  </link>  
 
  <joint name="servo_gripper_B" type="fixed">
    <parent link="gripper_link"/>
    <child link="gripper_link_B"/>  
    <origin xyz="0 0 0" rpy="0 0 0" />
	<axis xyz="1 0 0" />    
  </joint>  
 
  <link name="gripper_link_B">    
	<visual>
      <geometry>
        <box size="0.002 0.04 0.032"/>
      </geometry>
      <origin rpy="0 0 0" xyz="-0.025 0 0"/>
      <material name="white">
		<color rgba="1 1 1 1"/>
      </material>
    </visual>
    <collision>
      <origin rpy="0 0 0" xyz="-0.025 0 0"/>		
	  <geometry>
        <box size="0.002 0.04 0.032"/>
      </geometry>
    </collision>
    <inertial>
      <origin rpy="0 0 0" xyz="-0.025 0 0"/>		
      <mass value="0.0005"/>
	  <default_inertia />
    </inertial>           
  </link>
 
  <joint name="servo_gripper_D" type="fixed">
    <parent link="gripper_link"/>
    <child link="gripper_link_SI"/>  
    <origin xyz="0 0 0" rpy="0 0 0" />
	<axis xyz="1 0 0" />    
  </joint>  
 
  <link name="gripper_link_SI">    
	<visual>
      <geometry>
        <box size="0.0375 0.002 0.032"/>
      </geometry>
      <origin rpy="0 0 0" xyz="-0.00725 0.021 0"/>
      <material name="white">
		<color rgba="1 1 1 1"/>
      </material>
    </visual>
    <collision>
      <origin rpy="0 0 0" xyz="-0.00725 0.021 0"/>		
	  <geometry>
        <box size="0.0375 0.002 0.032"/>
      </geometry>
    </collision>
    <inertial>
      <origin rpy="0 0 0" xyz="-0.00725 0.021 0"/>			
      <mass value="0.0005"/>
	  <default_inertia />
    </inertial>        
  </link>
 
  <joint name="servo_gripper_I" type="fixed">
    <parent link="gripper_link"/>
    <child link="gripper_link_SD"/>  
    <origin xyz="0 0 0" rpy="0 0 0" />
	<axis xyz="1 0 0" />    
  </joint>  
 
  <link name="gripper_link_SD">    
	<visual>
      <geometry>
        <box size="0.0375 0.002 0.032"/>
      </geometry>
      <origin rpy="0 0 0" xyz="-0.00725 -0.021 0"/>
      <material name="white">
		<color rgba="1 1 1 1"/>
      </material>
    </visual>
    <collision>
      <origin rpy="0 0 0" xyz="-0.00725 -0.021 0"/>		
	  <geometry>
        <box size="0.0375 0.002 0.032"/>
      </geometry>
    </collision>
    <inertial>
      <origin rpy="0 0 0" xyz="-0.00725 -0.021 0"/>			
      <mass value="0.0005"/>
	  <default_inertia />
    </inertial>            
  </link>
 
</macro>
 
</robot>
