<?xml version='1.0'?>
<sdf version='1.5'>
  <model name='my_simple_arm'>
    <pose>-2.64679 0.318269 0.5 0 -0 0</pose>
    <link name='unit_sphere_0'>
      <pose>0.156065 0.681731 0 0 -0 0</pose>
      <gravity>1</gravity>
      <self_collide>0</self_collide>
      <kinematic>0</kinematic>
      <visual name='unit_sphere_0_visual'>
        <pose>0 0 0 0 -0 0</pose>
        <geometry>
          <sphere>
            <radius>0.5</radius>
          </sphere>
        </geometry>
        <material>
          <script>
            <uri>file://media/materials/scripts/gazebo.material</uri>
            <name>Gazebo/Grey</name>
          </script>
        </material>
      </visual>
      <collision name='unit_sphere_0_collision'>
        <geometry>
          <sphere>
            <radius>0.5</radius>
          </sphere>
        </geometry>
        <pose>0 0 0 0 -0 0</pose>
      </collision>
    </link>
    <link name='unit_cylinder_0'>
      <pose>-0.156065 -0.681731 0 0 -0 0</pose>
      <gravity>1</gravity>
      <self_collide>0</self_collide>
      <kinematic>0</kinematic>
      <visual name='unit_cylinder_0_visual'>
        <pose>0 0 0 0 -0 0</pose>
        <geometry>
          <cylinder>
            <radius>0.209968</radius>
            <length>1</length>
          </cylinder>
        </geometry>
        <material>
          <script>
            <uri>file://media/materials/scripts/gazebo.material</uri>
            <name>Gazebo/Grey</name>
          </script>
        </material>
      </visual>
      <collision name='unit_cylinder_0_collision'>
        <geometry>
          <cylinder>
            <radius>0.209968</radius>
            <length>1</length>
          </cylinder>
        </geometry>
        <pose>0 0 0 0 -0 0</pose>
      </collision>
    </link>
    <joint name='unit_cylinder_0_JOINT_1' type='ball'>
      <parent>unit_cylinder_0</parent>
      <child>unit_sphere_0</child>
      <axis>
        <xyz>0 0 1</xyz>
        <use_parent_model_frame>0</use_parent_model_frame>
        <limit>
          <lower>-1e+16</lower>
          <upper>1e+16</upper>
        </limit>
      </axis>
      <pose>0 0 0 0 -0 0</pose>
    </joint>
    <static>0</static>
    <allow_auto_disable>1</allow_auto_disable>
  </model>
</sdf>
